2021-03-12T17:23:25.762640+00:00 app[web.1]: File "/app/.heroku/python/lib/python3.6/site-packages/gunicorn/workers/sync.py", line 175, in handle_request
2021-03-12T17:23:25.762640+00:00 app[web.1]: respiter = self.wsgi(environ, resp.start_response)
2021-03-12T17:23:25.762674+00:00 app[web.1]: File "/app/.heroku/python/lib/python3.6/site-packages/flask/app.py", line 2464, in __call__
2021-03-12T17:23:25.762675+00:00 app[web.1]: return self.wsgi_app(environ, start_response)
2021-03-12T17:23:25.762700+00:00 app[web.1]: File "/app/.heroku/python/lib/python3.6/site-packages/flask/app.py", line 2450, in wsgi_app
2021-03-12T17:23:25.762701+00:00 app[web.1]: response = self.handle_exception(e)
2021-03-12T17:23:25.762725+00:00 app[web.1]: File "/app/.heroku/python/lib/python3.6/site-packages/flask/app.py", line 1871, in handle_exception
2021-03-12T17:23:25.762726+00:00 app[web.1]: self.log_exception((exc_type, exc_value, tb))
2021-03-12T17:23:25.762752+00:00 app[web.1]: File "/app/.heroku/python/lib/python3.6/site-packages/flask/app.py", line 1892, in log_exception
2021-03-12T17:23:25.762754+00:00 app[web.1]: "Exception on %s [%s]" % (request.path, request.method), exc_info=exc_info
2021-03-12T17:23:25.762799+00:00 app[web.1]: Message: 'Exception on /auth/login [GET]'
2021-03-12T17:23:25.762800+00:00 app[web.1]: Arguments: ()
2021-03-12T17:23:25.817728+00:00 app[web.1]: [2021-03-12 17:23:25 +0000] [15] [ERROR] Error handling request /auth/login?next=%2F
2021-03-12T17:23:25.817729+00:00 app[web.1]: Traceback (most recent call last):
2021-03-12T17:23:25.817730+00:00 app[web.1]: File "/app/.heroku/python/lib/python3.6/site-packages/flask/app.py", line 2447, in wsgi_app
2021-03-12T17:23:25.817730+00:00 app[web.1]: response = self.full_dispatch_request()
2021-03-12T17:23:25.817731+00:00 app[web.1]: File "/app/.heroku/python/lib/python3.6/site-packages/flask/app.py", line 1952, in full_dispatch_request
2021-03-12T17:23:25.817731+00:00 app[web.1]: rv = self.handle_user_exception(e)
2021-03-12T17:23:25.817732+00:00 app[web.1]: File "/app/.heroku/python/lib/python3.6/site-packages/flask/app.py", line 1821, in handle_user_exception
2021-03-12T17:23:25.817732+00:00 app[web.1]: reraise(exc_type, exc_value, tb)
2021-03-12T17:23:25.817732+00:00 app[web.1]: File "/app/.heroku/python/lib/python3.6/site-packages/flask/_compat.py", line 39, in reraise
2021-03-12T17:23:25.817733+00:00 app[web.1]: raise value
2021-03-12T17:23:25.817733+00:00 app[web.1]: File "/app/.heroku/python/lib/python3.6/site-packages/flask/app.py", line 1950, in full_dispatch_request
2021-03-12T17:23:25.817734+00:00 app[web.1]: rv = self.dispatch_request()
2021-03-12T17:23:25.817734+00:00 app[web.1]: File "/app/.heroku/python/lib/python3.6/site-packages/flask/app.py", line 1936, in dispatch_request
2021-03-12T17:23:25.817735+00:00 app[web.1]: return self.view_functions[rule.endpoint](**req.view_args)
2021-03-12T17:23:25.817735+00:00 app[web.1]: File "/app/app/auth/routes.py", line 27, in login
2021-03-12T17:23:25.817736+00:00 app[web.1]: return render_template('auth/login.html', title='Sign In', form=form)
2021-03-12T17:23:25.817736+00:00 app[web.1]: File "/app/.heroku/python/lib/python3.6/site-packages/flask/templating.py", line 140, in render_template
2021-03-12T17:23:25.817737+00:00 app[web.1]: ctx.app,
2021-03-12T17:23:25.817737+00:00 app[web.1]: File "/app/.heroku/python/lib/python3.6/site-packages/flask/templating.py", line 120, in _render
2021-03-12T17:23:25.817738+00:00 app[web.1]: rv = template.render(context)
2021-03-12T17:23:25.817738+00:00 app[web.1]: File "/app/.heroku/python/lib/python3.6/site-packages/jinja2/environment.py", line 1090, in render
2021-03-12T17:23:25.817742+00:00 app[web.1]: self.environment.handle_exception()
2021-03-12T17:23:25.817742+00:00 app[web.1]: File "/app/.heroku/python/lib/python3.6/site-packages/jinja2/environment.py", line 832, in handle_exception
2021-03-12T17:23:25.817743+00:00 app[web.1]: reraise(*rewrite_traceback_stack(source=source))
2021-03-12T17:23:25.817743+00:00 app[web.1]: File "/app/.heroku/python/lib/python3.6/site-packages/jinja2/_compat.py", line 28, in reraise
2021-03-12T17:23:25.817744+00:00 app[web.1]: raise value.with_traceback(tb)
2021-03-12T17:23:25.817744+00:00 app[web.1]: File "/app/app/templates/auth/login.html", line 2, in top-level template code
2021-03-12T17:23:25.817744+00:00 app[web.1]: {% import 'bootstrap/wtf.html' as wtf %}
2021-03-12T17:23:25.817745+00:00 app[web.1]: File "/app/app/templates/base.html", line 1, in top-level template code
2021-03-12T17:23:25.817745+00:00 app[web.1]: {% extends 'bootstrap/base.html' %}
2021-03-12T17:23:25.817745+00:00 app[web.1]: File "/app/.heroku/python/lib/python3.6/site-packages/flask_bootstrap/templates/bootstrap/base.html", line 1, in top-level template code
2021-03-12T17:23:25.817746+00:00 app[web.1]: {% block doc -%}
2021-03-12T17:23:25.817746+00:00 app[web.1]: File "/app/.heroku/python/lib/python3.6/site-packages/flask_bootstrap/templates/bootstrap/base.html", line 4, in block "doc"
2021-03-12T17:23:25.817747+00:00 app[web.1]: {%- block html %}
2021-03-12T17:23:25.817747+00:00 app[web.1]: File "/app/.heroku/python/lib/python3.6/site-packages/flask_bootstrap/templates/bootstrap/base.html", line 20, in block "html"
2021-03-12T17:23:25.817748+00:00 app[web.1]: {% block body -%}
2021-03-12T17:23:25.817748+00:00 app[web.1]: File "/app/.heroku/python/lib/python3.6/site-packages/flask_bootstrap/templates/bootstrap/base.html", line 21, in block "body"
2021-03-12T17:23:25.817748+00:00 app[web.1]: {% block navbar %}
2021-03-12T17:23:25.817749+00:00 app[web.1]: File "/app/app/templates/base.html", line 17, in block "navbar"
2021-03-12T17:23:25.817749+00:00 app[web.1]: <a class="navbar-brand" href="{{ url_for('index') }}">Microblog</a>
2021-03-12T17:23:25.817750+00:00 app[web.1]: File "/app/.heroku/python/lib/python3.6/site-packages/flask/helpers.py", line 370, in url_for
2021-03-12T17:23:25.817750+00:00 app[web.1]: return appctx.app.handle_url_build_error(error, endpoint, values)
2021-03-12T17:23:25.817750+00:00 app[web.1]: File "/app/.heroku/python/lib/python3.6/site-packages/flask/app.py", line 2216, in handle_url_build_error
2021-03-12T17:23:25.817751+00:00 app[web.1]: reraise(exc_type, exc_value, tb)
2021-03-12T17:23:25.817751+00:00 app[web.1]: File "/app/.heroku/python/lib/python3.6/site-packages/flask/_compat.py", line 39, in reraise
2021-03-12T17:23:25.817751+00:00 app[web.1]: raise value
2021-03-12T17:23:25.817752+00:00 app[web.1]: File "/app/.heroku/python/lib/python3.6/site-packages/flask/helpers.py", line 358, in url_for
2021-03-12T17:23:25.817752+00:00 app[web.1]: endpoint, values, method=method, force_external=external
2021-03-12T17:23:25.817752+00:00 app[web.1]: File "/app/.heroku/python/lib/python3.6/site-packages/werkzeug/routing.py", line 2179, in build
2021-03-12T17:23:25.817753+00:00 app[web.1]: raise BuildError(endpoint, values, method, self)
2021-03-12T17:23:25.817753+00:00 app[web.1]: werkzeug.routing.BuildError: Could not build url for endpoint 'index'. Did you mean 'main.index' instead?
2021-03-12T17:23:25.817754+00:00 app[web.1]: 
2021-03-12T17:23:25.817754+00:00 app[web.1]: During handling of the above exception, another exception occurred:
2021-03-12T17:23:25.817754+00:00 app[web.1]: 
2021-03-12T17:23:25.817755+00:00 app[web.1]: Traceback (most recent call last):
2021-03-12T17:23:25.817755+00:00 app[web.1]: File "/app/.heroku/python/lib/python3.6/site-packages/gunicorn/workers/sync.py", line 134, in handle
2021-03-12T17:23:25.817755+00:00 app[web.1]: self.handle_request(listener, req, client, addr)
2021-03-12T17:23:25.817756+00:00 app[web.1]: File "/app/.heroku/python/lib/python3.6/site-packages/gunicorn/workers/sync.py", line 175, in handle_request
2021-03-12T17:23:25.817756+00:00 app[web.1]: respiter = self.wsgi(environ, resp.start_response)
2021-03-12T17:23:25.817762+00:00 app[web.1]: File "/app/.heroku/python/lib/python3.6/site-packages/flask/app.py", line 2464, in __call__
2021-03-12T17:23:25.817762+00:00 app[web.1]: return self.wsgi_app(environ, start_response)
2021-03-12T17:23:25.817762+00:00 app[web.1]: File "/app/.heroku/python/lib/python3.6/site-packages/flask/app.py", line 2450, in wsgi_app
2021-03-12T17:23:25.817763+00:00 app[web.1]: response = self.handle_exception(e)
2021-03-12T17:23:25.817763+00:00 app[web.1]: File "/app/.heroku/python/lib/python3.6/site-packages/flask/app.py", line 1879, in handle_exception
2021-03-12T17:23:25.817763+00:00 app[web.1]: server_error = handler(server_error)
2021-03-12T17:23:25.817764+00:00 app[web.1]: File "/app/app/errors/handlers.py", line 14, in internal_error
2021-03-12T17:23:25.817764+00:00 app[web.1]: return render_template('errors/500.html'), 500
2021-03-12T17:23:25.817764+00:00 app[web.1]: File "/app/.heroku/python/lib/python3.6/site-packages/flask/templating.py", line 138, in render_template
2021-03-12T17:23:25.817765+00:00 app[web.1]: ctx.app.jinja_env.get_or_select_template(template_name_or_list),
2021-03-12T17:23:25.817765+00:00 app[web.1]: File "/app/.heroku/python/lib/python3.6/site-packages/jinja2/environment.py", line 930, in get_or_select_template
2021-03-12T17:23:25.817765+00:00 app[web.1]: return self.get_template(template_name_or_list, parent, globals)
2021-03-12T17:23:25.817766+00:00 app[web.1]: File "/app/.heroku/python/lib/python3.6/site-packages/jinja2/environment.py", line 883, in get_template
2021-03-12T17:23:25.817766+00:00 app[web.1]: return self._load_template(name, self.make_globals(globals))
2021-03-12T17:23:25.817767+00:00 app[web.1]: File "/app/.heroku/python/lib/python3.6/site-packages/jinja2/environment.py", line 857, in _load_template
2021-03-12T17:23:25.817767+00:00 app[web.1]: template = self.loader.load(self, name, globals)
2021-03-12T17:23:25.817767+00:00 app[web.1]: File "/app/.heroku/python/lib/python3.6/site-packages/jinja2/loaders.py", line 127, in load
2021-03-12T17:23:25.817768+00:00 app[web.1]: code = environment.compile(source, name, filename)
2021-03-12T17:23:25.817768+00:00 app[web.1]: File "/app/.heroku/python/lib/python3.6/site-packages/jinja2/environment.py", line 638, in compile
2021-03-12T17:23:25.817768+00:00 app[web.1]: self.handle_exception(source=source_hint)
2021-03-12T17:23:25.817769+00:00 app[web.1]: File "/app/.heroku/python/lib/python3.6/site-packages/jinja2/environment.py", line 832, in handle_exception
2021-03-12T17:23:25.817769+00:00 app[web.1]: reraise(*rewrite_traceback_stack(source=source))
2021-03-12T17:23:25.817770+00:00 app[web.1]: File "/app/.heroku/python/lib/python3.6/site-packages/jinja2/_compat.py", line 28, in reraise
2021-03-12T17:23:25.817770+00:00 app[web.1]: raise value.with_traceback(tb)
2021-03-12T17:23:25.817770+00:00 app[web.1]: File "/app/app/templates/errors/500.html", line 6, in template
2021-03-12T17:23:25.817771+00:00 app[web.1]: <p><a href="{{ url_for('index') }}">{{ _('Back') }}</a></p>
2021-03-12T17:23:25.817771+00:00 app[web.1]: jinja2.exceptions.TemplateSyntaxError: expected token ',', got 'index'
2021-03-12T17:23:25.818036+00:00 heroku[router]: at=info method=GET path="/auth/login?next=%2F" host=first1deployment-microblog.herokuapp.com request_id=6a313880-13a8-4156-99b9-a70652326735 fwd="149.154.161.20" dyno=web.1 connect=1ms service=439ms status=500 bytes=244 protocol=https
2021-03-12T17:23:25.818152+00:00 app[web.1]: 10.7.214.204 - - [12/Mar/2021:17:23:25 +0000] "GET /auth/login?next=%2F HTTP/1.1" 500 0 "-" "-"
2021-03-12T17:58:57.883379+00:00 heroku[web.1]: Idling
2021-03-12T17:58:57.885889+00:00 heroku[web.1]: State changed from up to down
2021-03-12T17:58:59.204127+00:00 heroku[web.1]: Stopping all processes with SIGTERM
2021-03-12T17:58:59.282119+00:00 app[web.1]: [2021-03-12 17:58:59 +0000] [15] [INFO] Worker exiting (pid: 15)
2021-03-12T17:58:59.387770+00:00 heroku[web.1]: Process exited with status 143
